<?xml version="1.0" ?>
<!-- =================================================================================== -->
<!-- |    This document was autogenerated by xacro from human.urdf.xacro               | -->
<!-- |    EDITING THIS FILE BY HAND IS NOT RECOMMENDED                                 | -->
<!-- =================================================================================== -->
<robot name="human" xmlns:xacro="http://www.ros.org/wiki/xacro">
  <material name="black">
    <color rgba="0.0 0.0 0.0 1.0"/>
  </material>
  <material name="blue">
    <color rgba="0.0 0.0 0.8 1.0"/>
  </material>
  <material name="green">
    <color rgba="0.0 0.8 0.0 1.0"/>
  </material>
  <material name="grey">
    <color rgba="0.6 0.6 0.6 1.0"/>
  </material>
  <material name="orange">
    <color rgba="1.0 0.423529411765 0.0392156862745 1.0"/>
  </material>
  <material name="brown">
    <color rgba="0.870588235294 0.811764705882 0.764705882353 1.0"/>
  </material>
  <material name="red">
    <color rgba="0.8 0.0 0.0 1.0"/>
  </material>
  <material name="white">
    <color rgba="1.0 1.0 1.0 1.0"/>
  </material>
  
  <!-- Used for fixing robot -->
  <link name="world"></link> 
    <joint name="world_fixed" type="fixed">
        <origin xyz="0 0 0.764" rpy="0 0 0"/>
        <parent link="world"/>
        <child link="base_link"/>
    </joint>

  <!-- base_link -->  
  <link name="base_link"/>
  <joint name="base_fixed" type="fixed">
    <origin rpy="0 0 0" xyz="0 0 0"/>
    <parent link="base_link"/>
    <child link="base_footprint"/>
  </joint>

  <!-- base_footprint --> 
  <link name="base_footprint">
    <visual>
      <origin rpy="0 0 0" xyz="0 0 0"/>
      <geometry>
        <mesh filename="package://human/meshes/base.STL" scale="1 1 1"/>
      </geometry>
      <material name="grey"/>
    </visual>
    <collision>
      <origin rpy="0 0 0" xyz="0 0 0"/>
      <geometry>
        <mesh filename="package://human/meshes/base.STL" scale="1 1 1"/>
      </geometry>
      <material name="grey"/>
    </collision>
    <inertial>
      <origin xyz="-0.00856879 0.00000000 -0.02356598"/>
      <mass value="0.664564"/>
      <inertia ixx="0.00504324" ixy="-0.00000002" ixz="-0.00000358" iyy="0.00051942" iyz="0.00000000" izz="0.00510248"/>
    </inertial>
  </link>

  <!-- imu joint -->
  <link name="imu_link"/> 
  <joint name="imu_fixed" type="fixed">
    <origin rpy="0 0 0" xyz="0.0 0 0.45"/>
    <parent link="base_footprint"/>
    <child link="imu_link"/>
  </joint>

  <!-- right hip yaw joint -->
  <joint name="r_hip_yaw_joint" type="revolute">
    <axis xyz="0 0 1"/>
    <origin rpy="0 0 ${-pi/2}" xyz="0.0 0.09 0.704"/>
    <parent link="base_footprint"/>
    <child link="r_hip_yaw_link"/>
    <limit effort="1000" lower="${-pi*0.9}" upper="${pi*0.9}" velocity="3"/>
    <dynamics damping="0.1" friction="0.0"/>
  </joint>
  <transmission name="r_hip_yaw_joint_tran">
    <type>transmission_interface/SimpleTransmission</type>
    <joint name="r_hip_yaw_joint">
      <hardwareInterface>hardware_interface/EffortJointInterface</hardwareInterface>
    </joint>
    <actuator name="r_hip_yaw_joint_motor">
      <hardwareInterface>EffortJointInterface</hardwareInterface>
      <mechanicalReduction>1</mechanicalReduction>
    </actuator>
  </transmission>

  <!-- right hip yaw link -->
  <link name="r_hip_yaw_link">
    <visual>
      <origin rpy="0 0 0" xyz="0 0 0"/>
      <geometry>
        <mesh filename="package://human/meshes/r_hip_yaw.STL" scale="1 1 1"/>
      </geometry>
      <material name="grey"/>
    </visual>
    <collision>
      <origin rpy="0 0 0" xyz="0 0 0"/>
      <geometry>
        <mesh filename="package://human/meshes/r_hip_yaw.STL" scale="1 1 1"/>
      </geometry>
      <material name="grey"/>
    </collision>
    <inertial>
      <origin xyz="0.00000000 -0.01999 -0.00735017"/>
      <mass value="0.090718"/>
      <inertia ixx="0.00014114" ixy="0.00000000" ixz="0.00000000" iyy="0.00002016" iyz="0.00000000" izz="0.00014272"/>
    </inertial>
  </link>
  
<!-- right hip roll joint-->
  <joint name="r_hip_roll_joint" type="revolute">
    <axis xyz="0 0 1"/>
    <origin rpy="${pi/2} 0 ${pi}" xyz="0 0 -0.036"/>
    <parent link="r_hip_yaw_link"/>
    <child link="r_hip_roll_link"/>
    <limit effort="1000" lower="${-pi*0.9}" upper="${pi*0.9}" velocity="3"/>
    <dynamics damping="0.1" friction="0.0"/>
  </joint>
  <transmission name="r_hip_roll_joint_tran">
    <type>transmission_interface/SimpleTransmission</type>
    <joint name="r_hip_roll_joint">
      <hardwareInterface>hardware_interface/EffortJointInterface</hardwareInterface>
    </joint>
    <actuator name="r_hip_roll_joint_motor">
      <hardwareInterface>EffortJointInterface</hardwareInterface>
      <mechanicalReduction>1</mechanicalReduction>
    </actuator>
  </transmission>

  <!-- right hip roll link -->
  <link name="r_hip_roll_link">
    <visual>
      <origin rpy="0 0 0" xyz="0 0 0"/>
      <geometry>
        <mesh filename="package://human/meshes/r_hip_roll.STL" scale="1 1 1"/>
      </geometry>
      <material name="grey"/>
    </visual>
    <collision>
      <origin rpy="0 0 0" xyz="0 0 0"/>
      <geometry>
        <mesh filename="package://human/meshes/r_hip_roll.STL" scale="1 1 1"/>
      </geometry>
      <material name="grey"/>
    </collision>
    <inertial>
      <origin xyz="-0.00005878 -0.01433229 -0.01958936"/>
      <mass value="0.342"/>
      <inertia ixx="0.00033963" ixy="0.00000054" ixz="-0.00000042" iyy="0.00029059" iyz="0.00001145" izz="0.00015024"/>
    </inertial>
  </link>

  <!-- right hip pitch joint -->
  <joint name="r_hip_pitch_joint" type="revolute">
    <axis xyz="0 0 1"/>
    <origin rpy="${-pi/2} 0 ${-pi/2}" xyz="0 0 0"/>
    <parent link="r_hip_roll_link"/>
    <child link="r_hip_pitch_link"/>
    <limit effort="1000" lower="${-pi*0.9}" upper="${pi*0.9}" velocity="3"/>
    <dynamics damping="0.1" friction="0.0"/>
  </joint>
  <transmission name="r_hip_pitch_joint_tran">
    <type>transmission_interface/SimpleTransmission</type>
    <joint name="r_hip_pitch_joint">
      <hardwareInterface>hardware_interface/EffortJointInterface</hardwareInterface>
    </joint>
    <actuator name="r_hip_pitch_joint_motor">
      <hardwareInterface>EffortJointInterface</hardwareInterface>
      <mechanicalReduction>1</mechanicalReduction>
    </actuator>
  </transmission>

  <!-- right hip pitch link -->
  <link name="r_hip_pitch_link">
    <visual>
      <origin rpy="0 0 0" xyz="0 0 0"/>
      <geometry>
        <mesh filename="package://human/meshes/r_hip_pitch.STL" scale="1 1 1"/>
      </geometry>
      <material name="grey"/>
    </visual>
    <collision>
      <origin rpy="0 0 0" xyz="0 0 0"/>
      <geometry>
        <mesh filename="package://human/meshes/r_hip_pitch.STL" scale="1 1 1"/>
      </geometry>
      <material name="grey"/>
    </collision>
    <inertial>
      <origin xyz="0.21422113 0.0 0.0"/>
      <mass value="0.33732478"/>
      <inertia ixx="0.00012533" ixy="0.00000000" ixz="0.00000079" iyy="0.00295762" iyz="0.00000000" izz="0.00291401"/>
    </inertial>
  </link>

  <!-- right knee pitch joint -->
  <joint name="r_knee_pitch_joint" type="revolute">
    <axis xyz="0 0 1"/>
    <origin rpy="0 0 0" xyz="0.3 0 0"/>
    <parent link="r_hip_pitch_link"/>
    <child link="r_knee_pitch_link"/>
    <limit effort="1000" lower="${-pi*0.9}" upper="${pi*0.9}" velocity="3"/>
    <dynamics damping="0.1" friction="0.0"/>
  </joint>
  <transmission name="r_knee_pitch_joint_tran">
    <type>transmission_interface/SimpleTransmission</type>
    <joint name="r_knee_pitch_joint">
      <hardwareInterface>hardware_interface/EffortJointInterface</hardwareInterface>
    </joint>
    <actuator name="r_knee_pitch_joint_motor">
      <hardwareInterface>EffortJointInterface</hardwareInterface>
      <mechanicalReduction>1</mechanicalReduction>
    </actuator>
  </transmission>

  <!-- right knee pitch link -->
  <link name="r_knee_pitch_link">
    <visual>
      <origin rpy="0 0 0" xyz="0 0 0"/>
      <geometry>
        <mesh filename="package://human/meshes/r_knee_pitch.STL" scale="1 1 1"/>
      </geometry>
      <material name="grey"/>
    </visual>
    <collision>
      <origin rpy="0 0 0" xyz="0 0 0"/>
      <geometry>
        <mesh filename="package://human/meshes/r_knee_pitch.STL" scale="1 1 1"/>
      </geometry>
      <material name="grey"/>
    </collision>
    <inertial>
      <origin xyz="0.16288151 0.00000000 0.00000000"/>
      <mass value="0.15100000"/>
      <inertia ixx="0.0000634" ixy="0.0" ixz="0.0" iyy="0.00139615" iyz="0.0" izz="0.00136734"/>
    </inertial>
  </link>

  <!-- right ankle pitch joint -->
  <joint name="r_ankle_pitch_joint" type="revolute">
    <axis xyz="0 0 1"/>
    <origin rpy="0 0 0" xyz="0.315 0 0"/>
    <parent link="r_knee_pitch_link"/>
    <child link="r_ankle_pitch_link"/>
    <limit effort="1000" lower="${-pi*0.9}" upper="${pi*0.9}" velocity="3"/>
    <dynamics damping="0.1" friction="0.0"/>
  </joint>
  <transmission name="r_ankle_pitch_joint_tran">
    <type>transmission_interface/SimpleTransmission</type>
    <joint name="r_ankle_pitch_joint">
      <hardwareInterface>hardware_interface/EffortJointInterface</hardwareInterface>
    </joint>
    <actuator name="r_ankle_pitch_joint_motor">
      <hardwareInterface>EffortJointInterface</hardwareInterface>
      <mechanicalReduction>1</mechanicalReduction>
    </actuator>
  </transmission>

  <!-- right ankle pitch link -->
  <link name="r_ankle_pitch_link">
    <visual>
      <origin rpy="0 0 0" xyz="0 0 0"/>
      <geometry>
        <mesh filename="package://human/meshes/r_ankle_pitch.STL" scale="1 1 1"/>
      </geometry>
      <material name="grey"/>
    </visual>
    <collision>
      <origin rpy="0 0 0" xyz="0 0 0"/>
      <geometry>
        <mesh filename="package://human/meshes/r_ankle_pitch.STL" scale="1 1 1"/>
      </geometry>
      <material name="grey"/>
    </collision>
    <inertial>
      <origin xyz="-0.01433229 0.01958936 0.00005878"/>
      <mass value="0.342"/>
      <inertia ixx="0.00029059" ixy="-0.00001145" ixz="-0.00000054" iyy="0.00015024" iyz="-0.00000042" izz="0.00033963"/>
    </inertial>
  </link>

  <!-- right ankle roll pitch -->
  <joint name="r_ankle_roll_joint" type="revolute">
    <axis xyz="0 0 1"/>
    <origin rpy="${pi/2} 0 0" xyz="0 0 0"/>
    <parent link="r_ankle_pitch_link"/>
    <child link="r_ankle_roll_link"/>
    <limit effort="1000" lower="${-pi*0.9}" upper="${pi*0.9}" velocity="3"/>
    <dynamics damping="0.1" friction="0.0"/>
  </joint>
  <transmission name="r_ankle_roll_joint_tran">
    <type>transmission_interface/SimpleTransmission</type>
    <joint name="r_ankle_roll_joint">
      <hardwareInterface>hardware_interface/EffortJointInterface</hardwareInterface>
    </joint>
    <actuator name="r_ankle_roll_joint_motor">
      <hardwareInterface>EffortJointInterface</hardwareInterface>
      <mechanicalReduction>1</mechanicalReduction>
    </actuator>
  </transmission>

  <!-- right ankle roll link -->
  <link name="r_ankle_roll_link">
    <visual>
      <origin rpy="0 0 0" xyz="0 0 0"/>
      <geometry>
        <mesh filename="package://human/meshes/r_ankle_roll.STL" scale="1 1 1"/>
      </geometry>
      <material name="grey"/>
    </visual>
    <collision>
      <origin rpy="0 0 0" xyz="0 0 0"/>
      <geometry>
        <mesh filename="package://human/meshes/r_ankle_roll.STL" scale="1 1 1"/>
      </geometry>
      <material name="grey"/>
    </collision>
    <inertial>
      <origin xyz="0.03627101 -0.00000116 0.00053793"/>
      <mass value="0.155"/>
      <inertia ixx="0.00052206" ixy="0" ixz="0.00001" iyy="0.00047025" iyz="0" izz="0.00009087"/>
    </inertial>
  </link>

  <!-- right ft fixed joint -->
  <joint name="r_ft_fixed" type="fixed">
    <origin rpy="0 ${-pi/2} 0" xyz="0.045 0.0 0.0"/>
    <parent link="r_ankle_roll_link"/>
    <child link="r_foot_ft_link"/>
  </joint>
  <!-- right foot ft link -->
  <link name="r_foot_ft_link"/>



  <!-- left hip yaw joint -->
  <joint name="l_hip_yaw_joint" type="revolute">
    <axis xyz="0 0 1"/>
    <origin rpy="0 0 ${pi/2}" xyz="0.0 0.09 -0.068"/>
    <parent link="base_footprint"/>
    <child link="l_hip_yaw_link"/>
    <limit effort="1000" lower="${-pi*0.9}" upper="${pi*0.9}" velocity="3"/>
    <dynamics damping="0.1" friction="0.0"/>
  </joint>
  <transmission name="l_hip_yaw_joint_tran">
    <type>transmission_interface/SimpleTransmission</type>
    <joint name="l_hip_yaw_joint">
      <hardwareInterface>hardware_interface/EffortJointInterface</hardwareInterface>
    </joint>
    <actuator name="l_hip_yaw_joint_motor">
      <hardwareInterface>EffortJointInterface</hardwareInterface>
      <mechanicalReduction>1</mechanicalReduction>
    </actuator>
  </transmission>

  <!-- left hip yaw link -->
  <link name="l_hip_yaw_link">
    <visual>
      <origin rpy="0 0 0" xyz="0 0 0"/>
      <geometry>
        <mesh filename="package://human/meshes/l_hip_yaw.STL" scale="1 1 1"/>
      </geometry>
      <material name="grey"/>
    </visual>
    <collision>
      <origin rpy="0 0 0" xyz="0 0 0"/>
      <geometry>
        <mesh filename="package://human/meshes/l_hip_yaw.STL" scale="1 1 1"/>
      </geometry>
      <material name="grey"/>
    </collision>
    <inertial>
      <origin xyz="0 0.01999 -0.00735017"/>
      <mass value="0.090718"/>
      <inertia ixx="0.00014114" ixy="0.0" ixz="0.0" iyy="0.00002016" iyz="0.0" izz="0.00014272"/>
    </inertial>
  </link>

  <!-- left hip roll joint-->
  <joint name="l_hip_roll_joint" type="revolute">
    <axis xyz="0 0 1"/>
    <origin rpy="${pi/2} 0 0" xyz="0 0 -0.036"/>
    <parent link="l_hip_yaw_link"/>
    <child link="l_hip_roll_link"/>
    <limit effort="1000" lower="${-pi*0.9}" upper="${pi*0.9}" velocity="3"/>
    <dynamics damping="0.1" friction="0.0"/>
  </joint>
  <transmission name="l_hip_roll_joint_tran">
    <type>transmission_interface/SimpleTransmission</type>
    <joint name="l_hip_roll_joint">
      <hardwareInterface>hardware_interface/EffortJointInterface</hardwareInterface>
    </joint>
    <actuator name="l_hip_roll_joint_motor">
      <hardwareInterface>EffortJointInterface</hardwareInterface>
      <mechanicalReduction>1</mechanicalReduction>
    </actuator>
  </transmission>

  <!-- left hip roll link -->
  <link name="l_hip_roll_link">
    <visual>
      <origin rpy="0 0 0" xyz="0 0 0"/>
      <geometry>
        <mesh filename="package://human/meshes/l_hip_roll.STL" scale="1 1 1"/>
      </geometry>
      <material name="grey"/>
    </visual>
    <collision>
      <origin rpy="0 0 0" xyz="0 0 0"/>
      <geometry>
        <mesh filename="package://human/meshes/l_hip_roll.STL" scale="1 1 1"/>
      </geometry>
      <material name="grey"/>
    </collision>
    <inertial>
      <origin xyz="-0.00005878 -0.01433229 -0.01958936"/>
      <mass value="0.342"/>
      <inertia ixx="0.00033963" ixy="0.00000054" ixz="-0.00000042" iyy="0.00029059" iyz="0.00001145" izz="0.00015024"/>
    </inertial>
  </link>

  <!-- left hip pitch joint -->
  <joint name="l_hip_pitch_joint" type="revolute">
    <axis xyz="0 0 1"/>
    <origin rpy="${-pi/2} 0 ${-pi/2}" xyz="0 0 0"/>
    <parent link="l_hip_roll_link"/>
    <child link="l_hip_pitch_link"/>
    <limit effort="1000" lower="${-pi*0.9}" upper="${pi*0.9}" velocity="3"/>
    <dynamics damping="0.1" friction="0.0"/>
  </joint>
  <transmission name="l_hip_pitch_joint_tran">
    <type>transmission_interface/SimpleTransmission</type>
    <joint name="l_hip_pitch_joint">
      <hardwareInterface>hardware_interface/EffortJointInterface</hardwareInterface>
    </joint>
    <actuator name="l_hip_pitch_joint_motor">
      <hardwareInterface>EffortJointInterface</hardwareInterface>
      <mechanicalReduction>1</mechanicalReduction>
    </actuator>
  </transmission>

  <!-- left hip pitch link -->
  <link name="l_hip_pitch_link">
    <visual>
      <origin rpy="0 0 0" xyz="0 0 0"/>
      <geometry>
        <mesh filename="package://human/meshes/l_hip_pitch.STL" scale="1 1 1"/>
      </geometry>
      <material name="grey"/>
    </visual>
    <collision>
      <origin rpy="0 0 0" xyz="0 0 0"/>
      <geometry>
        <mesh filename="package://human/meshes/l_hip_pitch.STL" scale="1 1 1"/>
      </geometry>
      <material name="grey"/>
    </collision>
    <inertial>
      <origin xyz="0.21422113 0.00000000 0.00000000"/>
      <mass value="0.33732478"/>
      <inertia ixx="0.00012533" ixy="0.00000000" ixz="0.00000079" iyy="0.00295762" iyz="0.00000000" izz="0.00291401"/>
    </inertial>
  </link>

  <!-- left knee pitch joint -->
  <joint name="l_knee_pitch_joint" type="revolute">
    <axis xyz="0 0 1"/>
    <origin rpy="0 0 0" xyz="0.3 0 0"/>
    <parent link="l_hip_pitch_link"/>
    <child link="l_knee_pitch_link"/>
    <limit effort="1000" lower="${-pi*0.9}" upper="${pi*0.9}" velocity="3"/>
    <dynamics damping="0.1" friction="0.0"/>
  </joint>
  <transmission name="l_knee_pitch_joint_tran">
    <type>transmission_interface/SimpleTransmission</type>
    <joint name="l_knee_pitch_joint">
      <hardwareInterface>hardware_interface/EffortJointInterface</hardwareInterface>
    </joint>
    <actuator name="l_knee_pitch_joint_motor">
      <hardwareInterface>EffortJointInterface</hardwareInterface>
      <mechanicalReduction>1</mechanicalReduction>
    </actuator>
  </transmission>

  <!-- left knee pitch link -->
  <link name="l_knee_pitch_link">
    <visual>
      <origin rpy="0 0 0" xyz="0 0 0"/>
      <geometry>
        <mesh filename="package://human/meshes/l_knee_pitch.STL" scale="1 1 1"/>
      </geometry>
      <material name="grey"/>
    </visual>
    <collision>
      <origin rpy="0 0 0" xyz="0 0 0"/>
      <geometry>
        <mesh filename="package://human/meshes/l_knee_pitch.STL" scale="1 1 1"/>
      </geometry>
      <material name="grey"/>
    </collision>
    <inertial>
      <origin xyz="0.16288151 0.00000000 0.00000000"/>
      <mass value="0.15100000"/>
      <inertia ixx="0.0000634" ixy="0.0" ixz="0.0" iyy="0.00139615" iyz="0.0" izz="0.00136734"/>
    </inertial>
  </link>

  <!-- left ankle pitch joint -->
  <joint name="l_ankle_pitch_joint" type="revolute">
    <axis xyz="0 0 1"/>
    <origin rpy="0 0 0" xyz="0.315 0 0"/>
    <parent link="l_knee_pitch_link"/>
    <child link="l_ankle_pitch_link"/>
    <limit effort="1000" lower="${-pi*0.9}" upper="${pi*0.9}" velocity="3"/>
    <dynamics damping="0.1" friction="0.0"/>
  </joint>
  <transmission name="l_ankle_pitch_joint_tran">
    <type>transmission_interface/SimpleTransmission</type>
    <joint name="l_ankle_pitch_joint">
      <hardwareInterface>hardware_interface/EffortJointInterface</hardwareInterface>
    </joint>
    <actuator name="l_ankle_pitch_joint_motor">
      <hardwareInterface>EffortJointInterface</hardwareInterface>
      <mechanicalReduction>1</mechanicalReduction>
    </actuator>
  </transmission>

  <!-- left ankle pitch link -->
  <link name="l_ankle_pitch_link">
    <visual>
      <origin rpy="0 0 0" xyz="0 0 0"/>
      <geometry>
        <mesh filename="package://human/meshes/l_ankle_pitch.STL" scale="1 1 1"/>
      </geometry>
      <material name="grey"/>
    </visual>
    <collision>
      <origin rpy="0 0 0" xyz="0 0 0"/>
      <geometry>
        <mesh filename="package://human/meshes/l_ankle_pitch.STL" scale="1 1 1"/>
      </geometry>
      <material name="grey"/>
    </collision>
    <inertial>
      <origin xyz="-0.01433229 0.01958936 0.00005878"/>
      <mass value="0.34200000"/>
      <inertia ixx="0.00029059" ixy="-0.00001145" ixz="-0.00000054" iyy="0.00015024" iyz="-0.00000042" izz="0.00033963"/>
    </inertial>
  </link>

  <!-- left ankle roll pitch -->
  <joint name="l_ankle_roll_joint" type="revolute">
    <axis xyz="0 0 1"/>
    <origin rpy="${pi/2}  0 0" xyz="0 0 0"/>
    <parent link="l_ankle_pitch_link"/>
    <child link="l_ankle_roll_link"/>
    <limit effort="1000" lower="${-pi*0.9}" upper="${pi*0.9}" velocity="3"/>
    <dynamics damping="0.1" friction="0.0"/>
  </joint>
  <transmission name="l_ankle_roll_joint_tran">
    <type>transmission_interface/SimpleTransmission</type>
    <joint name="l_ankle_roll_joint">
      <hardwareInterface>hardware_interface/EffortJointInterface</hardwareInterface>
    </joint>
    <actuator name="l_ankle_roll_joint_motor">
      <hardwareInterface>EffortJointInterface</hardwareInterface>
      <mechanicalReduction>1</mechanicalReduction>
    </actuator>
  </transmission>

  <!-- left ankle roll link -->
  <link name="l_ankle_roll_link">
    <visual>
      <origin rpy="0 0 0" xyz="0 0 0"/>
      <geometry>
        <mesh filename="package://human/meshes/l_ankle_roll.STL" scale="1 1 1"/>
      </geometry>
      <material name="grey"/>
    </visual>
    <collision>
      <origin rpy="0 0 0" xyz="0 0 0"/>
      <geometry>
        <mesh filename="package://human/meshes/l_ankle_roll.STL" scale="1 1 1"/>
      </geometry>
      <material name="grey"/>
    </collision>
    <inertial>
      <origin xyz="0.03627101 -0.00000116 0.00053793"/>
      <mass value="0.155"/>
      <inertia ixx="0.00052206" ixy="0.000000" ixz="0.00001" iyy="0.00047025" iyz="0" izz="0.00009087"/>
    </inertial>
  </link>

  <!-- left ft fixed joint -->
  <joint name="l_ft_fixed" type="fixed">
    <origin rpy="0 ${-pi/2} 0" xyz="0.045 0.0 0.0"/>
    <parent link="l_ankle_roll_link"/>
    <child link="l_foot_ft_link"/>
  </joint>

  <!-- left foot ft link -->
  <link name="l_foot_ft_link"/>  

</robot>
